Workbook

Sheet README
A1: WeekendAI Labs — 3-Year Operating Model
A2: Companion to the WeekendAI Labs Business Plan wiki (Financial Plan section). Internal operating plan, prepared Sep 2026.
A4: How to use
A5: 1. Edit only BLUE cells on the 'Assumptions' sheet (yellow-filled = key levers). Every other sheet recalculates.
A6: 2. 'Revenue' builds each of the 13 revenue lines from volume × price. 'P&L' adds COGS (via gross-margin inputs), opex and EBITDA.
A7: 3. 'KPIs' tracks unit economics against the deck targets. 'Deck Reconciliation' compares model output to the investor-deck figures.
A8: 4. 'Valuation' applies the three multiple benchmarks cited in the deck. 'Use of Funds' allocates the proposed $2.5M raise.
A10: Colour legend
A11: Blue text = hardcoded input · Black = formula · Green = link from another sheet · Yellow fill = key lever
A13: Source of inputs
A14: Prices ($79 / $149 / $497 / $79 pm / $2,500 / $6,000 / $25k–75k), Guild members, cohort graduates, B2B contract counts, facilitator bench and deck targets come from the WeekendAI Labs investor deck (user-supplied).
A15: Volumes for the other lines, average contract values, gross margins, headcount and opex ratios are modelling assumptions set to reconcile to the deck's revenue path — treat them as planning estimates, not facts.
... A19: Models a lean humans + AI agents team against the baseline hiring plan. Edit FTE, cost and agent-spend inputs in blue.

Sheet Assumptions
A1: Assumptions — edit blue cells only
A3: Revenue driver | B3: Year 1 | C3: Year 2 | D3: Year 3 | E3: Gross margin | F3: Source / note
A4: Workflow packs & toolkit | E4: 0.9 | F4: $79 pack / $149 toolkit blended (deck)
A5: Units sold | B5: 1200 | C5: 4500 | D5: 9000
A6: Avg price ($) | B6: 110 | C6: 110 | D6: 110
A7: AI Fluency Academy (evergreen) | E7: 0.9 | F7: $497 price (deck)
A8: Enrolments | B8: 500 | C8: 2000 | D8: 5000
A9: Price ($) | B9: 497 | C9: 497 | D9: 497
A10: Operator Guild membership | E10: 0.85 | F10: Year-end members & $79/mo (deck). Revenue uses average of opening & closing members
A11: Members, year-end | B11: 600 | C11: 1800 | D11: 3800
A12: Monthly fee ($) | B12: 79 | C12: 79 | D12: 79
A13: AI Operator Certification (6-wk cohort) | E13: 0.7 | F13: Seats = annual cohort graduates implied by deck (250 / 850 / 1,833 cumulative)
A14: Paid seats | B14: 250 | C14: 600 | D14: 983
A15: Price ($) | B15: 2500 | C15: 2500 | D15: 2500
A16: Executive AI Leadership Intensive | E16: 0.65 | F16: $6,000 price (deck); seat volumes = assumption
A17: Seats | B17: 15 | C17: 60 | D17: 175
A18: Price ($) | B18: 6000 | C18: 6000 | D18: 6000
A19: B2B team licences & enterprise programmes | E19: 0.6 | F19: Contract counts & $25k–75k band (deck); Y3 ACV above band assumes multi-year/expansion
A20: Active contracts | B20: 4 | C20: 15 | D20: 30
A21: Avg contract value ($) | B21: 40000 | C21: 50000 | D21: 80000
A22: Corporate workshops (one-off) | E22: 0.6 | F22: Assumption
A23: Workshops | B23: 6 | C23: 15 | D23: 30
A24: Avg fee ($) | B24: 10000 | C24: 12000 | D24: 14000
A25: Studios project work (sites, video, ads) | E25: 0.5 | F25: Assumption
A26: Projects | B26: 8 | C26: 20 | D26: 35
A27: Avg fee ($) | B27: 8000 | C27: 9000 | D27: 10000
A28: Studios agency retainers | E28: 0.55 | F28: Assumption; annualised ×12
A29: Avg active clients | B29: 2 | C29: 6 | D29: 12
A30: Monthly retainer ($) | B30: 3000 | C30: 3500 | D30: 4000
A31: Playbook & framework licensing | E31: 0.9 | F31: Assumption
A32: Licences | B32: 20 | C32: 60 | D32: 160
A33: Avg licence ($) | B33: 1000 | C33: 1667 | D33: 2500
A34: Sponsorships & partnerships | E34: 0.85 | F34: Assumption; annual contracts counted as contracted revenue
A35: Deals | B35: 3 | C35: 9 | D35: 20
A36: Avg deal ($) | B36: 10000 | C36: 20000 | D36: 25000
A37: Divine Chronicles YouTube (ad revenue) | E37: 0.7 | F37: Assumption — channel is monetised (deck); revenue level not disclosed
A38: Channel (flat) | B38: 1 | C38: 1 | D38: 1
A39: Annual revenue ($) | B39: 12000 | C39: 30000 | D39: 60000
A40: Merchandise & identity drops | E40: 0.6 | F40: Deck caps merch ≤6% of revenue; 55–65% apparel margin norm → model uses 60% GM
A41: Orders | B41: 250 | C41: 1200 | D41: 4000
...

Sheet Revenue
A1: Revenue build ($)
A3: Revenue line | B3: Pillar | C3: Brand | D3: Year 1 | E3: Year 2 | F3: Year 3 | G3: Recurring? | I3: CapabilityOS subscribers | J3: Year 1 | K3: Year 2 | L3: Year 3
A4: Workflow packs & toolkit | B4: 1 Digital Products | C4: School | D4: =Assumptions!$B$5*Assumptions!$B$6 -> 132000 | E4: =Assumptions!$C$5*Assumptions!$C$6 -> 495000 | F4: =Assumptions!$D$5*Assumptions!$D$6 -> 990000 | G4: No | I4: New paying subscribers | J4: =Assumptions!$B$44*Assumptions!$B$58 -> 300 | K4: =Assumptions!$C$44*Assumptions!$C$58 -> 1200 | L4: =Assumptions!$D$44*Assumptions!$D$58 -> 3000
A5: AI Fluency Academy (evergreen) | B5: 1 Digital Products | C5: School | D5: =Assumptions!$B$8*Assumptions!$B$9 -> 248500 | E5: =Assumptions!$C$8*Assumptions!$C$9 -> 994000 | F5: =Assumptions!$D$8*Assumptions!$D$9 -> 2485000 | G5: No | I5: Renewing subscribers | J5: 0 | K5: =Assumptions!$C$56*(J4+J5) -> 150 | L5: =Assumptions!$D$56*(K4+K5) -> 675
A6: Operator Guild membership | B6: 3 Community | C6: AI Edge | D6: =((0)+Assumptions!$B$11)/2*Assumptions!$B$12*12 -> 284400 | E6: =((Assumptions!$B$11)+Assumptions!$C$11)/2*Assumptions!$C$12*12 -> 1137600 | F6: =((Assumptions!$C$11)+Assumptions!$D$11)/2*Assumptions!$D$12*12 -> 2654400 | G6: Yes | I6: Paying subscribers in year | J6: =J4+J5 -> 300 | K6: =K4+K5 -> 1350 | L6: =L4+L5 -> 3675
A7: AI Operator Certification (6-wk cohort) | B7: 2 Transformation | C7: School | D7: =Assumptions!$B$14*Assumptions!$B$15 -> 625000 | E7: =Assumptions!$C$14*Assumptions!$C$15 -> 1500000 | F7: =Assumptions!$D$14*Assumptions!$D$15 -> 2457500 | G7: No | I7: Renewals are priced at the renewal share of list price.
A8: Executive AI Leadership Intensive | B8: 2 Transformation | C8: School | D8: =Assumptions!$B$17*Assumptions!$B$18 -> 90000 | E8: =Assumptions!$C$17*Assumptions!$C$18 -> 360000 | F8: =Assumptions!$D$17*Assumptions!$D$18 -> 1050000 | G8: No
A9: B2B team licences & enterprise programmes | B9: 2 Transformation | C9: School | D9: =Assumptions!$B$20*Assumptions!$B$21 -> 160000 | E9: =Assumptions!$C$20*Assumptions!$C$21 -> 750000 | F9: =Assumptions!$D$20*Assumptions!$D$21 -> 2400000 | G9: Yes
A10: Corporate workshops (one-off) | B10: 2 Transformation | C10: School | D10: =Assumptions!$B$23*Assumptions!$B$24 -> 60000 | E10: =Assumptions!$C$23*Assumptions!$C$24 -> 180000 | F10: =Assumptions!$D$23*Assumptions!$D$24 -> 420000 | G10: No
A11: Studios project work (sites, video, ads) | B11: 1 Digital Products | C11: Studios | D11: =Assumptions!$B$26*Assumptions!$B$27 -> 64000 | E11: =Assumptions!$C$26*Assumptions!$C$27 -> 180000 | F11: =Assumptions!$D$26*Assumptions!$D$27 -> 350000 | G11: No
A12: Studios agency retainers | B12: Portfolio | C12: Studios | D12: =Assumptions!$B$29*Assumptions!$B$30*12 -> 72000 | E12: =Assumptions!$C$29*Assumptions!$C$30*12 -> 252000 | F12: =Assumptions!$D$29*Assumptions!$D$30*12 -> 576000 | G12: Yes
A13: Playbook & framework licensing | B13: 1 Digital Products | C13: AI Edge | D13: =Assumptions!$B$32*Assumptions!$B$33 -> 20000 | E13: =Assumptions!$C$32*Assumptions!$C$33 -> 100020 | F13: =Assumptions!$D$32*Assumptions!$D$33 -> 400000 | G13: Yes
A14: Sponsorships & partnerships | B14: Portfolio | C14: WeekendAI Hub | D14: =Assumptions!$B$35*Assumptions!$B$36 -> 30000 | E14: =Assumptions!$C$35*Assumptions!$C$36 -> 180000 | F14: =Assumptions!$D$35*Assumptions!$D$36 -> 500000 | G14: Yes
A15: Divine Chronicles YouTube (ad revenue) | B15: 1 Digital Products | C15: Studios | D15: =Assumptions!$B$38*Assumptions!$B$39 -> 12000 | E15: =Assumptions!$C$38*Assumptions!$C$39 -> 30000 | F15: =Assumptions!$D$38*Assumptions!$D$39 -> 60000 | G15: No
A16: Merchandise & identity drops | B16: 4 Merchandise | C16: WeekendAI Hub | D16: =Assumptions!$B$41*Assumptions!$B$42 -> 10000 | E16: =Assumptions!$C$41*Assumptions!$C$42 -> 60000 | F16: =Assumptions!$D$41*Assumptions!$D$42 -> 250000 | G16: No
A17: CapabilityOS annual subscription (capos.live) | B17: 1 Digital Products | C17: School | D17: =(J4*Assumptions!$B$45+J5*Assumptions!$B$45*Assumptions!$B$57) -> 195000 | E17: =(K4*Assumptions!$C$45+K5*Assumptions!$C$45*Assumptions!$C$57) -> 828750 | F17: =(L4*Assumptions!$D$45+L5*Assumptions!$D$45*Assumptions!$D$57) -> 2169375 | G17: Yes
A18: CapabilityOS core package (one-time) | B18: 1 Digital Products | C18: School | D18: =Assumptions!$B$47*Assumptions!$B$48*Assumptions!$B$58 -> 39800 | E18: =Assumptions!$C$47*Assumptions!$C$48*Assumptions!$C$58 -> 159200 | F18: =Assumptions!$D$47*Assumptions!$D$48*Assumptions!$D$58 -> 398000 | G18: No
A19: Total revenue | D19: =SUM(D4:D18) -> 2042700 | E19: =SUM(E4:E18) -> 7206570 | F19: =SUM(F4:F18) -> 17160275
A21: Revenue mix
A22: Recurring + contracted revenue | D22: =SUMIF($G$4:$G$18,"Yes",D4:D18) -> 761400 | E22: =SUMIF($G$4:$G$18,"Yes",E4:E18) -> 3248370 | F22: =SUMIF($G$4:$G$18,"Yes",F4:F18) -> 8699775
A23: Recurring + contracted share | D23: =IF(D$19=0,0,D22/D$19) -> 0.37274196 | E23: =IF(E$19=0,0,E22/E$19) -> 0.45075119 | F23: =IF(F$19=0,0,F22/F$19) -> 0.50697177
A24: Merch share of revenue (guardrail ≤6%) | D24: =IF(D$19=0,0,D16/D$19) -> 0.0048954815 | E24: =IF(E$19=0,0,E16/E$19) -> 0.0083257361 | F24: =IF(F$19=0,0,F16/F$19) -> 0.014568531
A25: Merch guardrail check | D25: =IF(D24<=Assumptions!$B$55,"OK","OVER CAP") -> OK | E25: =IF(E24<=Assumptions!$C$55,"OK","OVER CAP") -> OK | F25: =IF(F24<=Assumptions!$D$55,"OK","OVER CAP") -> OK
A27: Revenue by pillar
A28: 1 Digital Products | D28: =SUMIF($B$4:$B$18,"1 Digital Products",D4:D18) -> 711300 | E28: =SUMIF($B$4:$B$18,"1 Digital Products",E4:E18) -> 2786970 | F28: =SUMIF($B$4:$B$18,"1 Digital Products",F4:F18) -> 6852375
A29: 2 Transformation | D29: =SUMIF($B$4:$B$18,"2 Transformation",D4:D18) -> 935000 | E29: =SUMIF($B$4:$B$18,"2 Transformation",E4:E18) -> 2790000 | F29: =SUMIF($B$4:$B$18,"2 Transformation",F4:F18) -> 6327500
A30: 3 Community | D30: =SUMIF($B$4:$B$18,"3 Community",D4:D18) -> 284400 | E30: =SUMIF($B$4:$B$18,"3 Community",E4:E18) -> 1137600 | F30: =SUMIF($B$4:$B$18,"3 Community",F4:F18) -> 2654400
A31: 4 Merchandise | D31: =SUMIF($B$4:$B$18,"4 Merchandise",D4:D18) -> 10000 | E31: =SUMIF($B$4:$B$18,"4 Merchandise",E4:E18) -> 60000 | F31: =SUMIF($B$4:$B$18,"4 Merchandise",F4:F18) -> 250000
A32: Portfolio | D32: =SUMIF($B$4:$B$18,"Portfolio",D4:D18) -> 102000 | E32: =SUMIF($B$4:$B$18,"Portfolio",E4:E18) -> 432000 | F32: =SUMIF($B$4:$B$18,"Portfolio",F4:F18) -> 1076000
A34: Revenue by brand
A35: School | D35: =SUMIF($C$4:$C$18,"School",D4:D18) -> 1550300 | E35: =SUMIF($C$4:$C$18,"School",E4:E18) -> 5266950 | F35: =SUMIF($C$4:$C$18,"School",F4:F18) -> 12369875
A36: Studios | D36: =SUMIF($C$4:$C$18,"Studios",D4:D18) -> 148000 | E36: =SUMIF($C$4:$C$18,"Studios",E4:E18) -> 462000 | F36: =SUMIF($C$4:$C$18,"Studios",F4:F18) -> 986000
A37: AI Edge | D37: =SUMIF($C$4:$C$18,"AI Edge",D4:D18) -> 304400 | E37: =SUMIF($C$4:$C$18,"AI Edge",E4:E18) -> 1237620 | F37: =SUMIF($C$4:$C$18,"AI Edge",F4:F18) -> 3054400
A38: WeekendAI Hub | D38: =SUMIF($C$4:$C$18,"WeekendAI Hub",D4:D18) -> 40000 | E38: =SUMIF($C$4:$C$18,"WeekendAI Hub",E4:E18) -> 240000 | F38: =SUMIF($C$4:$C$18,"WeekendAI Hub",F4:F18) -> 750000

Sheet P&L
A1: Profit & loss ($)
A3: Line | B3: Year 1 | C3: Year 2 | D3: Year 3
A4: Revenue | B4: =Revenue!D19 -> 2042700 | C4: =Revenue!E19 -> 7206570 | D4: =Revenue!F19 -> 17160275
A5: Cost of delivery (COGS) | B5: =Revenue!D4*(1-Assumptions!$E$4)+Revenue!D5*(1-Assumptions!$E$7)+Revenue!D6*(1-Assumptions!$E$10)+Revenue!D7*(1-Assumptions!$E$13)+Revenue!D8*(1-Assumptions!$E$16)+Revenue!D9*(1-Assumptions!$E$19)+Revenue!D10*(1-Assumptions!$E$22)+Revenue!D11*(1-Assumptions!$E$25)+Revenue!D12*(1-Assumptions!$E$28)+Revenue!D13*(1-Assumptions!$E$31)+Revenue!D14*(1-Assumptions!$E$34)+Revenue!D15*(1-Assumptions!$E$37)+Revenue!D16*(1-Assumptions!$E$40)+Revenue!D17*(1-Assumptions!$E$43)+Revenue!D18*(1-Assumptions!$E$46) -> 511180 | C5: =Revenue!E4*(1-Assumptions!$E$4)+Revenue!E5*(1-Assumptions!$E$7)+Revenue!E6*(1-Assumptions!$E$10)+Revenue!E7*(1-Assumptions!$E$13)+Revenue!E8*(1-Assumptions!$E$16)+Revenue!E9*(1-Assumptions!$E$19)+Revenue!E10*(1-Assumptions!$E$22)+Revenue!E11*(1-Assumptions!$E$25)+Revenue!E12*(1-Assumptions!$E$28)+Revenue!E13*(1-Assumptions!$E$31)+Revenue!E14*(1-Assumptions!$E$34)+Revenue!E15*(1-Assumptions!$E$37)+Revenue!E16*(1-Assumptions!$E$40)+Revenue!E17*(1-Assumptions!$E$43)+Revenue!E18*(1-Assumptions!$E$46) -> 1730572 | D5: =Revenue!F4*(1-Assumptions!$E$4)+Revenue!F5*(1-Assumptions!$E$7)+Revenue!F6*(1-Assumptions!$E$10)+Revenue!F7*(1-Assumptions!$E$13)+Revenue!F8*(1-Assumptions!$E$16)+Revenue!F9*(1-Assumptions!$E$19)+Revenue!F10*(1-Assumptions!$E$22)+Revenue!F11*(1-Assumptions!$E$25)+Revenue!F12*(1-Assumptions!$E$28)+Revenue!F13*(1-Assumptions!$E$31)+Revenue!F14*(1-Assumptions!$E$34)+Revenue!F15*(1-Assumptions!$E$37)+Revenue!F16*(1-Assumptions!$E$40)+Revenue!F17*(1-Assumptions!$E$43)+Revenue!F18*(1-Assumptions!$E$46) -> 4139185
A6: Gross profit | B6: =B4-B5 -> 1531520 | C6: =C4-C5 -> 5475998 | D6: =D4-D5 -> 13021090
A7: Gross margin | B7: =IF(B4=0,0,B6/B4) -> 0.74975278 | C7: =IF(C4=0,0,C6/C4) -> 0.7598619 | D7: =IF(D4=0,0,D6/D4) -> 0.75879262
A9: Operating expenses
A10: Content & paid acquisition | B10: =B4*Assumptions!$B$52 -> 714945 | C10: =C4*Assumptions!$C$52 -> 1729576.8 | D10: =D4*Assumptions!$D$52 -> 3603657.8
A11: Team (loaded payroll) | B11: =SUMPRODUCT(Assumptions!B62:B70,Assumptions!$E$62:$E$70) -> 430000 | C11: =SUMPRODUCT(Assumptions!C62:C70,Assumptions!$E$62:$E$70) -> 1305000 | D11: =SUMPRODUCT(Assumptions!D62:D70,Assumptions!$E$62:$E$70) -> 2325000
A12: Platform, tools & hosting | B12: =B4*Assumptions!$B$53 -> 81708 | C12: =C4*Assumptions!$C$53 -> 216197.1 | D12: =D4*Assumptions!$D$53 -> 429006.88
A13: G&A | B13: =B4*Assumptions!$B$54 -> 102135 | C13: =C4*Assumptions!$C$54 -> 288262.8 | D13: =D4*Assumptions!$D$54 -> 600609.62
A14: Total opex | B14: =SUM(B10:B13) -> 1328788 | C14: =SUM(C10:C13) -> 3539036.7 | D14: =SUM(D10:D13) -> 6958274.2
A16: EBITDA | B16: =B6-B14 -> 202732 | C16: =C6-C14 -> 1936961.3 | D16: =D6-D14 -> 6062815.8
A17: EBITDA margin | B17: =IF(B4=0,0,B16/B4) -> 0.099247075 | C17: =IF(C4=0,0,C16/C4) -> 0.26877714 | D17: =IF(D4=0,0,D16/D4) -> 0.35330528
A19: Headcount (FTE) | B19: =SUM(Assumptions!B62:B70) -> 5 | C19: =SUM(Assumptions!C62:C70) -> 15 | D19: =SUM(Assumptions!D62:D70) -> 28
A20: Revenue per FTE | B20: =IF(B19=0,0,B4/B19) -> 408540 | C20: =IF(C19=0,0,C4/C19) -> 480438 | D20: =IF(D19=0,0,D4/D19) -> 612866.96
A21: Cumulative EBITDA | B21: =B16 -> 202732 | C21: =B21+C16 -> 2139693.3 | D21: =C21+D16 -> 8202509

Sheet AI-Native Team
A1: AI-native operating model — humans + agents
A2: Alternative to the baseline team on the Assumptions sheet. Edit blue cells. Compares people + agent cost and EBITDA against the baseline P&L.
A4: Human role | B4: Y1 FTE | C4: Y2 FTE | D4: Y3 FTE | E4: Loaded cost ($) | F4: Supervises agents | G4: What stays human
A5: Founder / CEO | B5: 1 | C5: 1 | D5: 1 | E5: 150000 | F5: Content Studio, Curriculum | G5: Teaching flagship cohorts, founder voice, key enterprise relationships
A6: General Manager / COO | B6: 0 | C6: 1 | D6: 1 | E6: 165000 | F6: Finance & Admin | G6: P&L decisions, hiring, partner negotiations
A7: Head of AI Operations (first hire) | B7: 1 | C7: 1 | D7: 1 | E7: 90000 | F7: Cohort Ops, Concierge, Scout | G7: Designs workflows, owns agent quality, handles escalations
A8: Community lead / associate | B8: 0 | C8: 1 | D8: 2 | E8: 60000 | F8: Community Pulse | G8: Hosting events, welcome calls, churn-save conversations
A9: Creative & content lead / producer | B9: 1 | C9: 1 | D9: 2 | E9: 75000 | F9: Content Studio, Studios Production | G9: Creative direction, on-camera production, brand taste
A10: B2B & partnerships | B10: 0 | C10: 1 | D10: 2 | E10: 90000 | F10: Deal Desk | G10: Discovery calls, negotiation, sponsor relationships, renewals
A11: AI automation engineer | B11: 0 | C11: 1 | D11: 1 | E11: 110000 | F11: All (builds and evaluates) | G11: Agent build, integrations, evals, cost control
A12: Certified facilitators | B12: 0.5 | C12: 3 | D12: 8 | E12: 80000 | F12: Coach / TA, Proof | G12: Live teaching, feedback, certification decisions
A13: Studios lead | B13: 0 | C13: 0 | D13: 1 | E13: 85000 | F13: Studios Production | G13: Client relationships, creative sign-off
A14: CapabilityOS product & growth lead | B14: 0 | C14: 1 | D14: 1 | E14: 100000 | F14: CapabilityOS Coach | G14: Curriculum roadmap, live Q&A, subscriber retention and growth
A15: Human FTE | B15: =SUM(B5:B14) -> 3.5 | C15: =SUM(C5:C14) -> 11 | D15: =SUM(D5:D14) -> 20
A17: Cost build ($) | B17: Year 1 | C17: Year 2 | D17: Year 3 | G17: Note
A18: Human payroll (loaded) | B18: =SUMPRODUCT(B5:B14,$E$5:$E$14) -> 355000 | C18: =SUMPRODUCT(C5:C14,$E$5:$E$14) -> 1080000 | D18: =SUMPRODUCT(D5:D14,$E$5:$E$14) -> 1790000
A19: AI agents: model usage, agent platforms, AI media tools | B19: 30000 | C19: 90000 | D19: 180000 | G19: Assumption. Incremental to 'Platform, tools & hosting' on the P&L
A20: Freelancers: video editing, design, bookkeeping, legal | B20: 60000 | C20: 90000 | D20: 150000 | G20: Assumption. Human specialists on demand
A21: People + agents total | B21: =SUM(B18:B20) -> 445000 | C21: =SUM(C18:C20) -> 1260000 | D21: =SUM(D18:D20) -> 2120000
A23: Comparison to baseline | B23: Year 1 | C23: Year 2 | D23: Year 3 | G23: Note
A24: Baseline team cost (P&L) | B24: ='P&L'!B11 -> 430000 | C24: ='P&L'!C11 -> 1305000 | D24: ='P&L'!D11 -> 2325000 | G24: Conventional hiring plan, Assumptions sheet
A25: Baseline headcount | B25: ='P&L'!B19 -> 5 | C25: ='P&L'!C19 -> 15 | D25: ='P&L'!D19 -> 28
A26: Saving vs baseline (negative = costs more) | B26: =B24-B21 -> -15000 | C26: =C24-C21 -> 45000 | D26: =D24-D21 -> 205000
A27: Revenue | B27: ='P&L'!B4 -> 2042700 | C27: ='P&L'!C4 -> 7206570 | D27: ='P&L'!D4 -> 17160275
A28: Baseline EBITDA | B28: ='P&L'!B16 -> 202732 | C28: ='P&L'!C16 -> 1936961.3 | D28: ='P&L'!D16 -> 6062815.8
A29: AI-native EBITDA | B29: =B28+B26 -> 187732 | C29: =C28+C26 -> 1981961.3 | D29: =D28+D26 -> 6267815.8
A30: AI-native EBITDA margin | B30: =IF(B27=0,0,B29/B27) -> 0.091903853 | C30: =IF(C27=0,0,C29/C27) -> 0.27502145 | D30: =IF(D27=0,0,D29/D27) -> 0.36525147 | G30: Deck targets: ~5% / ~22% / ~30%
A31: Revenue per human FTE | B31: =IF(B15=0,0,B27/B15) -> 583628.57 | C31: =IF(C15=0,0,C27/C15) -> 655142.73 | D31: =IF(D15=0,0,D27/D15) -> 858013.75
A32: Baseline revenue per FTE | B32: ='P&L'!B20 -> 408540 | C32: ='P&L'!C20 -> 480438 | D32: ='P&L'!D20 -> 612866.96
A33: Facilitators as share of human FTE | B33: =IF(B15=0,0,B12/B15) -> 0.14285714 | C33: =IF(C15=0,0,C12/C15) -> 0.27272727 | D33: =IF(D15=0,0,D12/D15) -> 0.4 | G33: The human-touch core: teaching is where headcount should go
A34: Agent spend as share of people + agents | B34: =IF(B21=0,0,B19/B21) -> 0.06741573 | C34: =IF(C21=0,0,C19/C21) -> 0.071428571 | D34: =IF(D21=0,0,D19/D21) -> 0.08490566
A36: Reading this sheet: the saving is modest because facilitators are deliberately kept human. The gain is fewer coordination roles, higher revenue per person, and faster response times.

Sheet KPIs
A1: Unit economics & operating KPIs
A3: KPI | B3: Year 1 | C3: Year 2 | D3: Year 3 | E3: Deck target | F3: Status / note
A4: New paying customers (individual ladder) | B4: =(Assumptions!$B$5+Assumptions!$B$8+MAX(0,Assumptions!$B$11-0)+Assumptions!$B$14+Assumptions!$B$17+(Assumptions!$B$44+Assumptions!$B$47)*Assumptions!$B$58) -> 3065 | C4: =(Assumptions!$C$5+Assumptions!$C$8+MAX(0,Assumptions!$C$11-Assumptions!$B$11)+Assumptions!$C$14+Assumptions!$C$17+(Assumptions!$C$44+Assumptions!$C$47)*Assumptions!$C$58) -> 10360 | D4: =(Assumptions!$D$5+Assumptions!$D$8+MAX(0,Assumptions!$D$11-Assumptions!$C$11)+Assumptions!$D$14+Assumptions!$D$17+(Assumptions!$D$44+Assumptions!$D$47)*Assumptions!$D$58) -> 22158 | F4: Packs + Academy + net-new Guild + cohort + exec seats + new CapabilityOS subscribers and packages (upper bound; ignores overlap)
A5: Blended CAC ($) | B5: =IF(B4=0,0,'P&L'!B10/B4) -> 233.26101 | C5: =IF(C4=0,0,'P&L'!C10/C4) -> 166.94757 | D5: =IF(D4=0,0,'P&L'!D10/D4) -> 162.63461 | E5: 180 | F5: =IF(D5<=E5,"On target by Y3","Above target — needs organic/referral share") -> On target by Y3
A6: LTV — 2-yr Guild member, gross margin basis ($) | B6: =Assumptions!$B$12*12*Assumptions!$B$77*Assumptions!$E$10 -> 1611.6 | C6: =Assumptions!$C$12*12*Assumptions!$B$77*Assumptions!$E$10 -> 1611.6 | D6: =Assumptions!$D$12*12*Assumptions!$B$77*Assumptions!$E$10 -> 1611.6 | E6: 1600 | F6: =IF(B6>=E6,"Meets target","Below target") -> Meets target
A7: LTV : CAC | B7: =IF(B5=0,0,B6/B5) -> 6.9089986 | C7: =IF(C5=0,0,C6/C5) -> 9.6533302 | D7: =IF(D5=0,0,D6/D5) -> 9.9093297 | E7: 4 | F7: =IF(D7>=E7,"On target by Y3","Below 4:1 — fix CAC first") -> On target by Y3
A8: Recurring + contracted share | B8: =Revenue!D23 -> 0.37274196 | C8: =Revenue!E23 -> 0.45075119 | D8: =Revenue!F23 -> 0.50697177 | E8: 0.55 | F8: Deck: 20% / 40% / >55%
A9: Gross margin (blended) | B9: ='P&L'!B7 -> 0.74975278 | C9: ='P&L'!C7 -> 0.7598619 | D9: ='P&L'!D7 -> 0.75879262
A10: EBITDA margin | B10: ='P&L'!B17 -> 0.099247075 | C10: ='P&L'!C17 -> 0.26877714 | D10: ='P&L'!D17 -> 0.35330528 | E10: 0.3 | F10: Deck: ~5% / ~22% / ~30%
A11: Guild members (year-end) | B11: =Assumptions!$B$11 -> 600 | C11: =Assumptions!$C$11 -> 1800 | D11: =Assumptions!$D$11 -> 3800 | E11: 3800
A12: Cohort graduates (cumulative) | B12: =Assumptions!$B$14 -> 250 | C12: =Assumptions!$B$14+Assumptions!$C$14 -> 850 | D12: =Assumptions!$B$14+Assumptions!$C$14+Assumptions!$D$14 -> 1833 | E12: 1833 | F12: Assumes paid seats ≈ graduates
A13: B2B contracts | B13: =Assumptions!$B$20 -> 4 | C13: =Assumptions!$C$20 -> 15 | D13: =Assumptions!$D$20 -> 30 | E13: 30
A14: Facilitator bench | B14: =Assumptions!B69 -> 0 | C14: =Assumptions!C69 -> 3 | D14: =Assumptions!D69 -> 8 | E14: 8
A15: CapabilityOS paying subscribers in year | B15: =Revenue!J6 -> 300 | C15: =Revenue!K6 -> 1350 | D15: =Revenue!L6 -> 3675 | F15: New + renewing annual subscribers (capos.live)
A16: CapabilityOS share of revenue | B16: =IF(Revenue!D19=0,0,(Revenue!D17+Revenue!D18)/Revenue!D19) -> 0.1149459 | C16: =IF(Revenue!E19=0,0,(Revenue!E17+Revenue!E18)/Revenue!E19) -> 0.13709018 | D16: =IF(Revenue!F19=0,0,(Revenue!F17+Revenue!F18)/Revenue!F19) -> 0.14961153
A17: Guild MRR at year-end ($) | B17: =Assumptions!$B$11*Assumptions!$B$12 -> 47400 | C17: =Assumptions!$C$11*Assumptions!$C$12 -> 142200 | D17: =Assumptions!$D$11*Assumptions!$D$12 -> 300200
A18: Guild members per community manager | B18: =IF(Assumptions!B65=0,0,Assumptions!$B$11/Assumptions!B65) -> 600 | C18: =IF(Assumptions!C65=0,0,Assumptions!$C$11/Assumptions!C65) -> 900 | D18: =IF(Assumptions!D65=0,0,Assumptions!$D$11/Assumptions!D65) -> 1266.6667 | F18: Rule of thumb: keep below ~1,500 for a high-touch community

Sheet Valuation
A1: Implied valuation ($)
A3: Method | B3: Year 1 | C3: Year 2 | D3: Year 3 | E3: Basis
A4: Revenue | B4: =Revenue!D19 -> 2042700 | C4: =Revenue!E19 -> 7206570 | D4: =Revenue!F19 -> 17160275
A5: EBITDA | B5: ='P&L'!B16 -> 202732 | C5: ='P&L'!C16 -> 1936961.3 | D5: ='P&L'!D16 -> 6062815.8
A6: Base: EV/Sales × revenue | B6: =Revenue!D19*Assumptions!$B$74 -> 7149450 | C6: =Revenue!E19*Assumptions!$B$74 -> 25222995 | D6: =Revenue!F19*Assumptions!$B$74 -> 60060962 | E6: 3.5× EdTech median (deck headline)
A7: Downside: revenue multiple | B7: =Revenue!D19*Assumptions!$B$75 -> 3268320 | C7: =Revenue!E19*Assumptions!$B$75 -> 11530512 | D7: =Revenue!F19*Assumptions!$B$75 -> 27456440 | E7: 1.6× Q4 2024 EdTech median
A8: Cross-check: EV/EBITDA × EBITDA | B8: =MAX(0,'P&L'!B16)*Assumptions!$B$76 -> 3649176 | C8: =MAX(0,'P&L'!C16)*Assumptions!$B$76 -> 34865303 | D8: =MAX(0,'P&L'!D16)*Assumptions!$B$76 -> 1.0913068e+08 | E8: 18× EdTech EV/EBITDA
A10: Note: multiples are cited benchmarks, not a valuation opinion. A buyer will discount for founder dependency until founder-touch revenue is <30%.

Sheet Use of Funds
A1: Use of funds — proposed $2.5M raise
A3: Category | B3: Share | C3: Amount ($) | D3: What it buys
A4: Content & paid acquisition | B4: 0.35 | C4: =B4*Assumptions!$B$73 -> 875000 | D4: YouTube/LinkedIn production, paid ads, monthly free live workshop
A5: Product & curriculum build | B5: 0.25 | C5: =B5*Assumptions!$B$73 -> 625000 | D5: Record Academy, Certification curriculum, Scorecard, playbooks
A6: Facilitator & team bench | B6: 0.2 | C6: =B6*Assumptions!$B$73 -> 500000 | D6: Recruit, certify and license 8 facilitators; GM hire
A7: B2B sales & partnerships | B7: 0.12 | C7: =B7*Assumptions!$B$73 -> 300000 | D7: Enterprise sales lead, white-label partner channel
A8: Brand & merchandise | B8: 0.08 | C8: =B8*Assumptions!$B$73 -> 200000 | D8: Brand system across four properties; certification drops
A9: Total | B9: =SUM(B4:B8) -> 1 | C9: =SUM(C4:C8) -> 2500000 | D9: =IF(ROUND(B9,4)=1,"Allocation sums to 100%","CHECK: allocation ≠ 100%") -> Allocation sums to 100%

Sheet Deck Reconciliation
A1: Model vs investor-deck targets
A3: Metric | B3: Deck Y1 | C3: Model Y1 | D3: Deck Y2 | E3: Model Y2 | F3: Deck Y3 | G3: Model Y3 | H3: Y3 variance
A4: Revenue ($) | B4: 1800000 | C4: =Revenue!D19 -> 2042700 | D4: 6200000 | E4: =Revenue!E19 -> 7206570 | F4: 14600000 | G4: =Revenue!F19 -> 17160275 | H4: =G4-F4 -> 2560275
A5: Revenue excl. CapabilityOS ($) | B5: 1800000 | C5: =Revenue!D19-Revenue!D17-Revenue!D18 -> 1807900 | D5: 6200000 | E5: =Revenue!E19-Revenue!E17-Revenue!E18 -> 6218620 | F5: 14600000 | G5: =Revenue!F19-Revenue!F17-Revenue!F18 -> 14592900 | H5: =G5-F5 -> -7100
A6: Recurring + contracted share | B6: 0.2 | C6: =Revenue!D23 -> 0.37274196 | D6: 0.4 | E6: =Revenue!E23 -> 0.45075119 | F6: 0.55 | G6: =Revenue!F23 -> 0.50697177 | H6: =G6-F6 -> -0.043028229
A7: EBITDA margin | B7: 0.05 | C7: ='P&L'!B17 -> 0.099247075 | D7: 0.22 | E7: ='P&L'!C17 -> 0.26877714 | F7: 0.3 | G7: ='P&L'!D17 -> 0.35330528 | H7: =G7-F7 -> 0.053305279
A8: Guild members | B8: 600 | C8: =Assumptions!$B$11 -> 600 | D8: 1800 | E8: =Assumptions!$C$11 -> 1800 | F8: 3800 | G8: =Assumptions!$D$11 -> 3800 | H8: =G8-F8 -> 0
A9: B2B contracts | B9: 4 | C9: =Assumptions!$B$20 -> 4 | D9: 15 | E9: =Assumptions!$C$20 -> 15 | F9: 30 | G9: =Assumptions!$D$20 -> 30 | H9: =G9-F9 -> 0
A10: Facilitator bench | B10: 0 | C10: =Assumptions!B69 -> 0 | D10: 3 | E10: =Assumptions!C69 -> 3 | F10: 8 | G10: =Assumptions!D69 -> 8 | H10: =G10-F10 -> 0
A11: Implied valuation @3.5× ($) | B11: 6300000 | C11: =Valuation!B6 -> 7149450 | D11: 21700000 | E11: =Valuation!C6 -> 25222995 | F11: 51000000 | G11: =Valuation!D6 -> 60060962 | H11: =G11-F11 -> 9060962.5
A13: Deck figures: WeekendAI Labs investor deck, slide 17 (user-supplied). The deck predates CapabilityOS, so total revenue now runs above it; the excl. CapabilityOS row matches the deck. Founder-touch revenue (70% / 45% / <30%) is tracked operationally, not modelled.
